Workbook

Sheet INV
C5: Trošak osnivačkog ulaganja | D5: Cijena (€) | I5: Trošak investicije | J5: Cijena (€)
C6: Pravni troškovi i notarski honorari | D6: 500 | I6: Trošak registracije društva | J6: 5000
C7: Trošak registracije u Trgovačkom sudu | D7: 350 | I7: Preuređenje objekta | J7: 5000
C8: Trošak za izradu pečata i dokumentacije | D8: 30 | I8: Nabava opreme | J8: 62580
C9: Trošak oglašavanja u medijima i web stranici | D9: 620 | I9: Ostali troškovi (marketing, edukacija, materijali) | J9: 12500
C10: Ostali operativni troškovi | D10: 1000 | I10: Kupnja skladišta | J10: 27500
C11: Temeljni kapital za otvaranje d.o.o | D11: 2500 | I11: Ukupna investicija | J11: =SUM(J6:J10) -> 112580
C12: SVEUKUPNO TROŠKOVI | D12: =SUM(D6:D11) -> 5000 | K12: 112580
K13: =112580-85080 -> 27500
C16: Naziv opreme | D16: Cijena (€) | E16: Količina | F16: Iznos (€)
C17: Automatski pakirni stroj | D17: 20000 | E17: 1 | F17: =D17*E17 -> 20000
C18: Ručni paletni viličar | D18: 1500 | E18: 2 | F18: =D18*E18 -> 3000
C19: Transportna traka | D19: 15000 | E19: 1 | F19: =D19*E19 -> 15000
C20: IT oprema (računala, softver) | D20: 5000 | E20: 1 | F20: =D20*E20 -> 5000
C21: Kartonske kutije | D21: 1 | E21: 5000 | F21: =D21*E21 -> 5000
C22: Folija | D22: 1 | E22: 500 | F22: =D22*E22 -> 500
C23: Ljepljive trake | D23: 2 | E23: 500 | F23: =D23*E23 -> 1000
C24: Naljepnice | D24: 1 | E24: 4000 | F24: =D24*E24 -> 4000
C25: Kombi | D25: 5000 | E25: 1 | F25: =D25*E25 -> 5000
C26: Ostala oprema | D26: =19580-15500 -> 4080 | E26: - | F26: =D26 -> 4080
C27: Ukupno | F27: =SUM(F17:F26) -> 62580

Sheet INV+AM
A1: Struktura ulaganja
A2: Opis | B2: 2013 | C2: Iznos | D2: Vlastita sredstva | E2: Kredit
A3: A. Ulaganje u osnovna sredstva
A4: 1. | B4: Osnivačka ulaganja | C4: 5000 | D4: =C4 -> 5000
A5: 2. | B5: Građevinski objekt | C5: 27500 | D5: =C5 -> 27500
A6: 3. | B6: Oprema | C6: 62580 | E6: =C6 -> 62580
A7: B. Ulaganje u trajna obrtna sredstva | C7: =12500+5000 -> 17500 | D7: =C7 -> 17500
A8: C. Ukupan iznos ulaganja | C8: =SUM(C4:C7) -> 112580 | D8: =SUM(D4:D7) -> 50000 | E8: =SUM(E4:E7) -> 62580
D9: =D8/C8 -> 0.44412862 | E9: =E8/C8 -> 0.55587138 | F9: Ulaganje
A13: Obračun amortizacije
A14: Opis | C14: Iznos | D14: Postotak amortizacije | E14: Amortizacije
A15: A. Ulaganje u osnovna sredstva
A16: 1. | B16: Osnivačka ulaganja | C16: =C4 -> 5000 | D16: 0.25 | E16: =C16*D16 -> 1250
A17: 2. | B17: Građevinski objekt | C17: =C5 -> 27500 | D17: 0.05 | E17: =C17*D17 -> 1375
A18: 3. | B18: Oprema | C18: =C6 -> 62580 | D18: 0.2 | E18: =C18*D18 -> 12516
A19: Ukupan iznos amortizacije | C19: =SUM(C16:C18) -> 95080 | E19: =SUM(E16:E18) -> 15141
A21: Prikaz amortizacije
A22: Red.br. | B22: NAZIV | C22: Nabavna vrijednost investicije | D22: Stopa otpisa | E22: Godine rada projekta
E23: 1 | F23: 2 | G23: 3 | H23: 4 | I23: 5 | J23: OVP
E24: 2026 | F24: 2027 | G24: 2028 | H24: 2029 | I24: 2030
A25: A | B25: INVESTICIJA
A26: 1 | B26: Osnivačka ulaganja | C26: =C16 -> 5000 | D26: =D16 -> 0.25 | E26: =E16 -> 1250 | F26: =E16 -> 1250 | G26: =E16 -> 1250 | H26: =E16 -> 1250 | I26: 0 | J26: =C26-SUM(E26:I26) -> 0
A27: 2 | B27: Građevinski objekt | C27: =C17 -> 27500 | D27: =D17 -> 0.05 | E27: =$E$17 -> 1375 | F27: =$E$17 -> 1375 | G27: =$E$17 -> 1375 | H27: =$E$17 -> 1375 | I27: =$E$17 -> 1375 | J27: =C27-SUM(E27:I27) -> 20625
A28: 3 | B28: Oprema | C28: =C18 -> 62580 | D28: =D18 -> 0.2 | E28: =E18 -> 12516 | F28: =E18 -> 12516 | G28: =E18 -> 12516 | H28: =E18 -> 12516 | I28: =E18 -> 12516 | J28: =C28-SUM(E28:I28) -> 0
A29: B | B29: SVEUKUPNO | C29: =SUM(C26:C28) -> 95080 | E29: =SUM(E26:E28) -> 15141 | F29: =SUM(F26:F28) -> 15141 | G29: =SUM(G26:G28) -> 15141 | H29: =SUM(H26:H28) -> 15141 | I29: =SUM(I26:I28) -> 13891 | J29: =C29-SUM(E29:I29) -> 20625
A30: C | B30: OST. VRIJED. PROJEKTA | J30: =C30-SUM(E30:I30) -> 0
A31: 1 | B31: Osnovna sred. | C31: =C29 -> 95080 | E31: =C31-E29 -> 79939 | F31: =E31-F29 -> 64798 | G31: =F31-G29 -> 49657 | H31: =G31-H29 -> 34516 | I31: =H31-I29 -> 20625 | J31: =C31-SUM(E31:I31) -> -154455
A32: 2 | B32: TOBS | C32: =C7 -> 17500 | E32: =TOBS!D30 -> -14588.873 | F32: =TOBS!E30 -> -14510.628 | G32: =TOBS!F30 -> -13137.563 | H32: =TOBS!G30 -> -13564.357 | I32: =TOBS!H30 -> -13384.744 | J32: =C32-SUM(E32:I32) -> 86686.165
A33: 3 | B33: UKUPNO | C33: =SUM(C31:C32) -> 112580 | E33: =SUM(E31:E32) -> 65350.127 | F33: =SUM(F31:F32) -> 50287.372 | G33: =SUM(G31:G32) -> 36519.437 | H33: =SUM(H31:H32) -> 20951.643 | I33: =SUM(I31:I32) -> 7240.256 | J33: =C33-SUM(E33:I33) -> -67768.835

Sheet PRIHODI
C3: 2026 | D3: Usluga | E3: Jedinica mjere | F3: Broj paketa | G3: Jedinična cijena | H3: Ukupni mjesečni prihodi | I3: Ukupni godišnji prihodi
D4: Pakiranje | E4: Količina | F4: 2212 | G4: 4 | H4: =F4*G4 -> 8848 | I4: =12*H4 -> 106176
D5: Dostava paketa | E5: Količina | F5: 2212 | G5: 6 | H5: =F5*G5 -> 13272 | I5: =12*H5 -> 159264
D6: Ukupno | G6: =G4+G5 -> 10 | H6: =H4+H5 -> 22120 | I6: =I4+I5 -> 265440
C8: 2027 | D8: Usluga | E8: Jedinica mjere | F8: Broj paketa | G8: Jedinična cijena | H8: Ukupni mjesečni prihodi | I8: Ukupni godišnji prihodi
D9: Pakiranje | E9: Količina | F9: 1442 | G9: 4 | H9: =F9*G9 -> 5768 | I9: =12*H9 -> 69216
D10: Dostava paketa | E10: Količina | F10: 1442 | G10: 6 | H10: =F10*G10 -> 8652 | I10: =12*H10 -> 103824
D11: Ukupno | G11: =G9+G10 -> 10 | H11: =H9+H10 -> 14420 | I11: =I9+I10 -> 173040
C14: 2028 | D14: Usluga | E14: Jedinica mjere | F14: Broj paketa | G14: Jedinična cijena | H14: Ukupni mjesečni prihodi | I14: Ukupni godišnji prihodi
D15: Pakiranje | E15: Količina | F15: 3560 | G15: 4 | H15: =F15*G15 -> 14240 | I15: =12*H15 -> 170880
D16: Dostava paketa | E16: Količina | F16: 3560 | G16: 6 | H16: =F16*G16 -> 21360 | I16: =12*H16 -> 256320
D17: Ukupno | G17: =G15+G16 -> 10 | H17: =H15+H16 -> 35600 | I17: =I15+I16 -> 427200
C21: 2029 | D21: Usluga | E21: Jedinica mjere | F21: Broj paketa | G21: Jedinična cijena | H21: Ukupni mjesečni prihodi | I21: Ukupni godišnji prihodi
D22: Pakiranje | E22: Količina | F22: 1690 | G22: 4 | H22: =F22*G22 -> 6760 | I22: =12*H22 -> 81120
D23: Dostava paketa | E23: Količina | F23: 1690 | G23: 6 | H23: =F23*G23 -> 10140 | I23: =12*H23 -> 121680
D24: Ukupno | G24: =G22+G23 -> 10 | H24: =H22+H23 -> 16900 | I24: =I22+I23 -> 202800
C27: 2030 | D27: Usluga | E27: Jedinica mjere | F27: Broj paketa | G27: Jedinična cijena | H27: Ukupni mjesečni prihodi | I27: Ukupni godišnji prihodi
D28: Pakiranje | E28: Količina | F28: 2040 | G28: 4 | H28: =F28*G28 -> 8160 | I28: =12*H28 -> 97920
D29: Dostava paketa | E29: Količina | F29: 2040 | G29: 6 | H29: =F29*G29 -> 12240 | I29: =12*H29 -> 146880
D30: Ukupno | G30: =G28+G29 -> 10 | H30: =H28+H29 -> 20400 | I30: =I28+I29 -> 244800

Sheet RASHODI
C3: 2026 | D3: Mjesečni trošak | E3: Godišnji trošak | H3: 2027 | I3: Mjesečni trošak | J3: Godišnji trošak | O3: Naziv radnog mjesta | P3: Broj zaposlenih | Q3: KV. Struktura | R3: Neto plaća po zaposleniku | S3: Bruto plaća po zaposleniku | T3: Neto plaća | U3: Bruto plaća | V3: Ukupna godišnja plaća
C4: Troškovi energenata | D4: 900 | E4: =12*D4 -> 10800 | H4: Troškovi energenata | I4: 800 | J4: =12*I4 -> 9600 | O4: Radnik u skladištu | P4: 3 | Q4: NSS | R4: 700 | S4: =R4*1.7 -> 1190 | T4: =P4*R4 -> 2100 | U4: =P4*S4 -> 3570 | V4: =12*U4 -> 42840
C5: Servisiranje | D5: 700 | E5: =12*D5 -> 8400 | H5: Servisiranje | I5: 600 | J5: =12*I5 -> 7200 | O5: Vozač | P5: 1 | Q5: NSS | R5: 700 | S5: =R5*1.7 -> 1190 | T5: =P5*R5 -> 700 | U5: =P5*S5 -> 1190 | V5: =12*U5 -> 14280
C6: Oglašavanje | D6: 150 | E6: =12*D6 -> 1800 | H6: Oglašavanje | I6: 100 | J6: =12*I6 -> 1200 | O6: Administrativni djelatnik | P6: 1 | Q6: VŠS | R6: 800 | S6: =R6*1.7 -> 1360 | T6: =P6*R6 -> 800 | U6: =P6*S6 -> 1360 | V6: =12*U6 -> 16320
C7: Plaće | D7: 6120 | E7: =12*D7 -> 73440 | H7: Plaće | I7: 6120 | J7: =12*I7 -> 73440 | O7: UKUPNO: | P7: =SUM(P4:P6) -> 5 | R7: =SUM(R4:R6) -> 2200 | S7: =SUM(S4:S6) -> 3740 | T7: =SUM(T4:T6) -> 3600 | U7: =SUM(U4:U6) -> 6120 | V7: =SUM(V4:V6) -> 73440
C8: Materijali za pakiranje | D8: 1546 | E8: =12*D8 -> 18552 | H8: Materijali za pakiranje | I8: 1056 | J8: =12*I8 -> 12672
C9: Ostali troškovi | D9: 500 | E9: =12*D9 -> 6000 | H9: Ostali troškovi | I9: 250 | J9: =12*I9 -> 3000
C10: UKUPNO | D10: =SUM(D4:D9) -> 9916 | E10: =SUM(E4:E9) -> 118992 | H10: UKUPNO | I10: =SUM(I4:I9) -> 8926 | J10: =SUM(J4:J9) -> 107112
C14: 2028 | D14: Mjesečni trošak | E14: Godišnji trošak | H14: 2029 | I14: Mjesečni trošak | J14: Godišnji trošak
C15: Troškovi energenata | D15: 1000 | E15: =12*D15 -> 12000 | H15: Troškovi energenata | I15: 650 | J15: =12*I15 -> 7800
C16: Servisiranje | D16: 800 | E16: =12*D16 -> 9600 | H16: Servisiranje | I16: 300 | J16: =12*I16 -> 3600
C17: Oglašavanje | D17: 0 | E17: =12*D17 -> 0 | H17: Oglašavanje | I17: 50 | J17: =12*I17 -> 600
C18: Plaće | D18: 6120 | E18: =12*D18 -> 73440 | H18: Plaće | I18: 6120 | J18: =12*I18 -> 73440
C19: Materijali za pakiranje | D19: 1760 | E19: =12*D19 -> 21120 | H19: Materijali za pakiranje | I19: 1200 | J19: =12*I19 -> 14400
C20: Ostali troškovi | D20: 450 | E20: =12*D20 -> 5400 | H20: Ostali troškovi | I20: 150 | J20: =12*I20 -> 1800
C21: UKUPNO | D21: =SUM(D15:D20) -> 10130 | E21: =SUM(E15:E20) -> 121560 | H21: UKUPNO | I21: =SUM(I15:I20) -> 8470 | J21: =SUM(J15:J20) -> 101640
C25: 2030 | D25: Mjesečni trošak | E25: Godišnji trošak
C26: Troškovi energenata | D26: 700 | E26: =12*D26 -> 8400
C27: Servisiranje | D27: 400 | E27: =12*D27 -> 4800
C28: Oglašavanje | D28: 70 | E28: =12*D28 -> 840
C29: Plaće | D29: 6120 | E29: =12*D29 -> 73440
C30: Materijali za pakiranje | D30: 1400 | E30: =12*D30 -> 16800
C31: Ostali troškovi | D31: 250 | E31: =12*D31 -> 3000
C32: UKUPNO | D32: =SUM(D26:D31) -> 8940 | E32: =SUM(E26:E31) -> 107280

Sheet KREDIT
B3: Kredit | C3: 62580 | F3: Godišnje | G3: 2026 | H3: 2027 | I3: 2028 | J3: 2029 | K3: 2030 | L3: 2031 | M3: Ukupno
B4: Poček | C4: 1 | F4: Otplata | G4: 0 | H4: =SUM(H19:H30) -> 11536.855 | I4: =SUM(H31:H42) -> 12006.885 | J4: =SUM(H43:H54) -> 12496.064 | K4: =SUM(H55:H66) -> 13005.173 | L4: =SUM(H67:H78) -> 13535.023 | M4: =SUM(G4:L4) -> 62580
B5: Otplata kredita | F5: Kamate | G5: =G18 -> 2503.2 | H5: =SUM(G19:G30) -> 2293.216 | I5: =SUM(G31:G42) -> 1823.1867 | J5: =SUM(G43:G54) -> 1334.0077 | K5: =SUM(G55:G66) -> 824.89875 | L5: =SUM(G67:G78) -> 295.04795 | M5: =SUM(G5:L5) -> 9073.557
B6: Naknada za obradu kredita | C6: 0.005 | F6: UKUPNO | G6: =SUM(G4:G5) -> 2503.2 | H6: =SUM(H4:H5) -> 13830.071 | I6: =SUM(I4:I5) -> 13830.071 | J6: =SUM(J4:J5) -> 13830.071 | K6: =SUM(K4:K5) -> 13830.071 | L6: =SUM(L4:L5) -> 13830.071 | M6: =SUM(G6:L6) -> 71653.557
B7: Visina anuiteta | C7: =PMT(C13,C9,C10,C11)*-1 -> 1152.506 | F7: =C7*12 -> 13830.071
B8: Godišnja kamatna stopa | C8: 4%
B9: Broj anuiteta | C9: 60
B10: Visina zajma | C10: 62580
B11: Prenumerando (1) ili postnumeradno (0) | C11: 0
B12: Broj ukamaćivanja tijekom godine - m | C12: 12
B13: Relativna kamatna stopa | C13: =C8/C12 -> 0.0033333333
B14: Broj godina počeka | C14: 1
E17: Godina | F17: Anuitet | G17: Kamate | H17: Otplatna kvota | I17: Ostatak duga
E18: Poček | G18: =C8*I18 -> 2503.2 | I18: =C3 -> 62580
E19: 1 | F19: =C7 -> 1152.506 | G19: =I18*C$13 -> 208.6 | H19: =F19-G19 -> 943.90595 | I19: =IF(E19="","",I18-H19) -> 61636.094
E20: 2 | F20: =F19 -> 1152.506 | G20: =I19*C$13 -> 205.45365 | H20: =F20-G20 -> 947.0523 | I20: =IF(E20="","",I19-H20) -> 60689.042
E21: 3 | F21: =F20 -> 1152.506 | G21: =I20*C$13 -> 202.29681 | H21: =F21-G21 -> 950.20914 | I21: =IF(E21="","",I20-H21) -> 59738.833
E22: 4 | F22: =F21 -> 1152.506 | G22: =I21*C$13 -> 199.12944 | H22: =F22-G22 -> 953.37651 | I22: =IF(E22="","",I21-H22) -> 58785.456
E23: 5 | F23: =F22 -> 1152.506 | G23: =I22*C$13 -> 195.95152 | H23: =F23-G23 -> 956.55443 | I23: =IF(E23="","",I22-H23) -> 57828.902
E24: 6 | F24: =F23 -> 1152.506 | G24: =I23*C$13 -> 192.76301 | H24: =F24-G24 -> 959.74294 | I24: =IF(E24="","",I23-H24) -> 56869.159
E25: 7 | F25: =F24 -> 1152.506 | G25: =I24*C$13 -> 189.56386 | H25: =F25-G25 -> 962.94209 | I25: =IF(E25="","",I24-H25) -> 55906.217
E26: 8 | F26: =F25 -> 1152.506 | G26: =I25*C$13 -> 186.35406 | H26: =F26-G26 -> 966.15189 | I26: =IF(E26="","",I25-H26) -> 54940.065
E27: 9 | F27: =F26 -> 1152.506 | G27: =I26*C$13 -> 183.13355 | H27: =F27-G27 -> 969.3724 | I27: =IF(E27="","",I26-H27) -> 53970.692
E28: 10 | F28: =F27 -> 1152.506 | G28: =I27*C$13 -> 179.90231 | H28: =F28-G28 -> 972.60364 | I28: =IF(E28="","",I27-H28) -> 52998.089
E29: 11 | F29: =F28 -> 1152.506 | G29: =I28*C$13 -> 176.6603 | H29: =F29-G29 -> 975.84565 | I29: =IF(E29="","",I28-H29) -> 52022.243
E30: 12 | F30: =F29 -> 1152.506 | G30: =I29*C$13 -> 173.40748 | H30: =F30-G30 -> 979.09847 | I30: =IF(E30="","",I29-H30) -> 51043.145
E31: 13 | F31: =F30 -> 1152.506 | G31: =I30*C$13 -> 170.14382 | H31: =F31-G31 -> 982.36214 | I31: =IF(E31="","",I30-H31) -> 50060.782
... E78: 60 | F78: =F77 -> 1152.506 | G78: =I77*C$13 -> 3.8289234 | H78: =F78-G78 -> 1148.677 | I78: =IF(E78="","",I77-H78) -> -1.0231815e-11

Sheet RDG
B2: RDG | C2: 2026 | D2: 2027 | E2: 2028 | F2: 2029 | G2: 2030
B3: Prihodi | C3: =PRIHODI!I6 -> 265440 | D3: =PRIHODI!I11 -> 173040 | E3: =PRIHODI!I17 -> 427200 | F3: =PRIHODI!I24 -> 202800 | G3: =PRIHODI!I30 -> 244800
B4: Rashodi Ukupno | C4: =SUM(C5:C10,C12:C13) -> 136636.2 | D4: =SUM(D5:D10,D12:D13) -> 124546.22 | E4: =SUM(E5:E10,E12:E13) -> 138524.19 | F4: =SUM(F5:F10,F12:F13) -> 118115.01 | G4: =SUM(G5:G10,G12:G13) -> 121995.9
B5: Troškovi energenata | C5: =900*12 -> 10800 | D5: =12*800 -> 9600 | E5: =12*1000 -> 12000 | F5: =12*650 -> 7800 | G5: =12*700 -> 8400
B6: Servisiranje | C6: =700*12 -> 8400 | D6: =12*600 -> 7200 | E6: =12*800 -> 9600 | F6: =12*300 -> 3600 | G6: =12*400 -> 4800
B7: Oglašavanje | C7: =150*12 -> 1800 | D7: =12*100 -> 1200 | E7: =12*0 -> 0 | F7: =12*50 -> 600 | G7: =12*70 -> 840
B8: Plaće | C8: =12*6120 -> 73440 | D8: =12*6120 -> 73440 | E8: =12*6120 -> 73440 | F8: =12*6120 -> 73440 | G8: =12*6120 -> 73440
B9: Materijali za pakiranje | C9: =12*1546 -> 18552 | D9: =12*1056 -> 12672 | E9: =12*1760 -> 21120 | F9: =12*1200 -> 14400 | G9: =12*1400 -> 16800
B10: Ostali troškovi | C10: =12*500 -> 6000 | D10: =12*250 -> 3000 | E10: 5400 | F10: =12*150 -> 1800 | G10: =12*250 -> 3000
B11: EBITDA | C11: =C3-SUM(C5:C10) -> 146448 | D11: =D3-SUM(D5:D10) -> 65928 | E11: =E3-SUM(E5:E10) -> 305640 | F11: =F3-SUM(F5:F10) -> 101160 | G11: =G3-SUM(G5:G10) -> 137520
B12: Amortizacija | C12: 15141 | D12: 15141 | E12: 15141 | F12: 15141 | G12: 13891
B13: Kamate | C13: 2503.2 | D13: 2293.216 | E13: 1823.1867 | F13: 1334.0077 | G13: 824.89875
B14: Dobit prije poreza | C14: =C11-C12-C13 -> 128803.8 | D14: =D11-D12-D13 -> 48493.784 | E14: =E11-E12-E13 -> 288675.81 | F14: =F11-F12-F13 -> 84684.992 | G14: =G11-G12-G13 -> 122804.1
B15: Porez(20%) | C15: =C14*20% -> 25760.76 | D15: =D14*20% -> 9698.7568 | E15: =E14*20% -> 57735.163 | F15: =F14*20% -> 16936.998 | G15: =G14*20% -> 24560.82
B16: Neto dobit | C16: =C14-C15 -> 103043.04 | D16: =D14-D15 -> 38795.027 | E16: =E14-E15 -> 230940.65 | F16: =F14-F15 -> 67747.994 | G16: =G14-G15 -> 98243.281
B20: Ocjena osjetljivosti projekta (2026)
B21: 1. FIKSNI TROŠKOVI | C21: =SUM(C22:C25) -> 95404.2
B22: Amortizacija | C22: =C12 -> 15141
B23: Trošak plaća (k+r) | C23: =C8 -> 73440 | F23: Gmin | G23: =C21/(C3-C26) -> 0.42551648
B24: Kamate | C24: =C13 -> 2503.2 | F24: Jmin | G24: =(C21+C26)/C3 -> 0.51475362
B25: Trošak energije(40%) | C25: =C5*40% -> 4320
B26: 2. VARIJABILNI TROŠKOVI: | C26: =SUM(C27:C31) -> 41232
B27: Trošak oglašavanja | C27: =C7 -> 1800
B28: Trošak materijala za pakiranje | C28: =C9 -> 18552
B29: Trošak servisiranja | C29: =C6 -> 8400
B30: Trošak energije(60%) | C30: =C5*60% -> 6480
B31: Ostali troškovi usluga | C31: =C10 -> 6000
B32: 3. UKUPNI TROŠKOVI: | C32: =SUM(C21+C26) -> 136636.2

Sheet TOBS
A1: Potreban TOBS | B1: Column1 | C1: Column2 | D1: 2026 | E1: 2027 | F1: 2028 | G1: 2029 | H1: 2030
A2: Stavka | B2: DV | C2: KO | D2: Ukupna svota | E2: Ukupna svota | F2: Ukupna svota | G2: Ukupna svota | H2: Ukupna svota
A3: Materijali za pakiranje | B3: 30 | C3: =365/B3 -> 12.166667 | D3: =RDG!C9 -> 18552 | E3: =RDG!D9 -> 12672 | F3: =RDG!E9 -> 21120 | G3: =RDG!F9 -> 14400 | H3: =RDG!G9 -> 16800
A4: Servisiranje | B4: 30 | C4: =365/B4 -> 12.166667 | D4: =RDG!C6 -> 8400 | E4: =RDG!D6 -> 7200 | F4: =RDG!E6 -> 9600 | G4: =RDG!F6 -> 3600 | H4: =RDG!G6 -> 4800
A5: Oglašavanje | B5: 30 | C5: =365/B5 -> 12.166667 | D5: =RDG!C7 -> 1800 | E5: =RDG!D7 -> 1200 | F5: =RDG!E7 -> 0 | G5: =RDG!F7 -> 600 | H5: =RDG!G7 -> 840
A6: Kupci | B6: 7 | C6: =365/B6 -> 52.142857 | D6: =RDG!C3 -> 265440 | E6: =RDG!D3 -> 173040 | F6: =RDG!E3 -> 427200 | G6: =RDG!F3 -> 202800 | H6: =RDG!G3 -> 244800
A7: Novac | B7: 3 | C7: =365/B7 -> 121.66667 | D7: =D6 -> 265440 | E7: =E6 -> 173040 | F7: =F6 -> 427200 | G7: =G6 -> 202800 | H7: =H6 -> 244800
A8: Ukupna potrebna sredstva
A9: Dobavljači | B9: 30 | C9: =365/B9 -> 12.166667 | D9: =SUM(RDG!C5:C6,RDG!C9:C10) -> 43752 | E9: =SUM(RDG!D5:D6,RDG!D9:D10) -> 32472 | F9: =SUM(RDG!E5:E6,RDG!E9:E10) -> 48120 | G9: =SUM(RDG!F5:F6,RDG!F9:F10) -> 27600 | H9: =SUM(RDG!G5:G6,RDG!G9:G10) -> 33000
A10: Plaće | B10: 30 | C10: =365/B10 -> 12.166667 | D10: =RDG!C8 -> 73440 | E10: =RDG!D8 -> 73440 | F10: =RDG!E8 -> 73440 | G10: =RDG!F8 -> 73440 | H10: =RDG!G8 -> 73440
A11: Amortizacija | B11: 30 | C11: =365/B11 -> 12.166667 | D11: =RDG!C12 -> 15141 | E11: =RDG!D12 -> 15141 | F11: =RDG!E12 -> 15141 | G11: =RDG!F12 -> 15141 | H11: =RDG!G12 -> 13891
A12: Porezi | B12: 30 | C12: =365/B12 -> 12.166667 | D12: =RDG!C15 -> 25760.76 | E12: =RDG!D15 -> 9698.7568 | F12: =RDG!E15 -> 57735.163 | G12: =RDG!F15 -> 16936.998 | H12: =RDG!G15 -> 24560.82
A13: Rashodi financiranja | B13: 30 | C13: =365/B13 -> 12.166667 | D13: =RDG!C4 -> 136636.2 | E13: =RDG!D4 -> 124546.22 | F13: =RDG!E4 -> 138524.19 | G13: =RDG!F4 -> 118115.01 | H13: =RDG!G4 -> 121995.9
A16: Potreban TOBS | B16: Column1 | C16: Column2 | D16: 2026 | E16: 2027 | F16: 2028 | G16: 2029 | H16: 2030
A17: Stavka | B17: DV | C17: KO | D17: Potreban iznos | E17: Potreban iznos | F17: Potreban iznos | G17: Potreban iznos | H17: Potreban iznos
A18: Materijali za pakiranje | B18: 30 | C18: =365/B18 -> 12.166667 | D18: =D3/$C3 -> 1524.8219 | E18: =E3/$C3 -> 1041.5342 | F18: =F3/$C3 -> 1735.8904 | G18: =G3/$C3 -> 1183.5616 | H18: =H3/$C3 -> 1380.8219
A19: Servisiranje | B19: 30 | C19: =365/B19 -> 12.166667 | D19: =D4/$C4 -> 690.41096 | E19: =E4/$C4 -> 591.78082 | F19: =F4/$C4 -> 789.0411 | G19: =G4/$C4 -> 295.89041 | H19: =H4/$C4 -> 394.52055
A20: Oglašavanje | B20: 30 | C20: =365/B20 -> 12.166667 | D20: =D5/$C5 -> 147.94521 | E20: =E5/$C5 -> 98.630137 | F20: =F5/$C5 -> 0 | G20: =G5/$C5 -> 49.315068 | H20: =H5/$C5 -> 69.041096
A21: Kupci | B21: 7 | C21: =365/B21 -> 52.142857 | D21: =D6/$C6 -> 5090.6301 | E21: =E6/$C6 -> 3318.5753 | F21: =F6/$C6 -> 8192.8767 | G21: =G6/$C6 -> 3889.3151 | H21: =H6/$C6 -> 4694.7945
A22: Novac | B22: 3 | C22: =365/B22 -> 121.66667 | D22: =D7/$C7 -> 2181.6986 | E22: =E7/$C7 -> 1422.2466 | F22: =F7/$C7 -> 3511.2329 | G22: =G7/$C7 -> 1666.8493 | H22: =H7/$C7 -> 2012.0548
A23: Ukupna potrebna sredstva | D23: =SUM(D18:D22) -> 9635.5068 | E23: =SUM(E18:E22) -> 6472.7671 | F23: =SUM(F18:F22) -> 14229.041 | G23: =SUM(G18:G22) -> 7084.9315 | H23: =SUM(H18:H22) -> 8551.2329
A24: Dobavljači | B24: 30 | C24: =365/B24 -> 12.166667 | D24: =D9/$C9 -> 3596.0548 | E24: =E9/$C9 -> 2668.9315 | F24: =F9/$C9 -> 3955.0685 | G24: =G9/$C9 -> 2268.4932 | H24: =H9/$C9 -> 2712.3288
A25: Plaće | B25: 30 | C25: =365/B25 -> 12.166667 | D25: =D10/$C10 -> 6036.1644 | E25: =E10/$C10 -> 6036.1644 | F25: =F10/$C10 -> 6036.1644 | G25: =G10/$C10 -> 6036.1644 | H25: =H10/$C10 -> 6036.1644
A26: Amortizacija | B26: 30 | C26: =365/B26 -> 12.166667 | D26: =D11/$C11 -> 1244.4658 | E26: =E11/$C11 -> 1244.4658 | F26: =F11/$C11 -> 1244.4658 | G26: =G11/$C11 -> 1244.4658 | H26: =H11/$C11 -> 1141.726
A27: Porezi | B27: 30 | C27: =365/B27 -> 12.166667 | D27: =D12/$C12 -> 2117.3227 | E27: =E12/$C12 -> 797.15809 | F27: =F12/$C12 -> 4745.3558 | G27: =G12/$C12 -> 1392.0821 | H27: =H12/$C12 -> 2018.6976
A28: Rashodi financiranja | B28: 30 | C28: =365/B28 -> 12.166667 | D28: =D13/$C13 -> 11230.373 | E28: =E13/$C13 -> 10236.675 | F28: =F13/$C13 -> 11385.55 | G28: =G13/$C13 -> 9708.0828 | H28: =H13/$C13 -> 10027.06
A29: Izvori iz poslovanja | D29: =SUM(D24:D28) -> 24224.38 | E29: =SUM(E24:E28) -> 20983.395 | F29: =SUM(F24:F28) -> 27366.604 | G29: =SUM(G24:G28) -> 20649.288 | H29: =SUM(H24:H28) -> 21935.977
A30: TRAJNA OBRTNA SREDSTVA | D30: =D23-D29 -> -14588.873 | E30: =E23-E29 -> -14510.628 | F30: =F23-F29 -> -13137.563 | G30: =G23-G29 -> -13564.357 | H30: =H23-H29 -> -13384.744

Sheet ET I FT
A1: Rentabilnost projekta
A2: EKONOMSKI TOK | K2: Proračun diskontiranog povrata sredstava | L2: Diskontna stopa | M2: 0.04
A3: OPIS | B3: 2025 | C3: 2026 | D3: 2027 | E3: 2028 | F3: 2029 | G3: 2030 | K3: Godina projekta | L3: 0 | M3: 1 | N3: 2 | O3: 3 | P3: 4 | Q3: 5
B4: 0 | C4: 1 | D4: 2 | E4: 3 | F4: 4 | G4: 5 | K4: DNT | L4: =B16*1/(1+$M$2)^L3 -> -112580 | M4: =C16*1/(1+$M$2)^M3 -> 130073.19 | N4: =D16*1/(1+$M$2)^N3 -> 51914.754 | O4: =E16*1/(1+$M$2)^O3 -> 219165.85 | P4: =F16*1/(1+$M$2)^P3 -> 72359 | Q4: =G16*1/(1+$M$2)^Q3 -> 98647.546
A5: I PRIMICI | B5: 0 | C5: =SUM(C6:C7) -> 265440 | D5: =SUM(D6:D7) -> 173040 | E5: =SUM(E6:E7) -> 427200 | F5: =SUM(F6:F7) -> 202800 | G5: =SUM(G6:G7) -> 252040.26 | K5: Kumulativ DNT | L5: =L4 -> -112580 | M5: =L5+M4 -> 17493.186 | N5: =M5+N4 -> 69407.94 | O5: =N5+O4 -> 288573.79 | P5: =O5+P4 -> 360932.79 | Q5: =P5+Q4 -> 459580.33
A6: Ukupni prihod | C6: =RDG!C3 -> 265440 | D6: =RDG!D3 -> 173040 | E6: =RDG!E3 -> 427200 | F6: =RDG!F3 -> 202800 | G6: =RDG!G3 -> 244800
A7: Ostatak vrijednosti projekta | G7: =SUM(G8:G9) -> 7240.256 | K7: Diskontirano vrijeme povrata | L7: =P3+(-Q4)/P5 -> 3.7266872
A8: Osnovnih sredstava | G8: ='INV+AM'!I31 -> 20625
A9: Obrtnih sredstava | G9: =TOBS!H30 -> -13384.744 | K9: NPV(4%) | L9: =SUM(M4:Q4)+L4 -> 459580.33 | M9: =NPV(M2,C16:J16)-B11 -> 459580.33
A10: II IZDACI | B10: =SUM(B11:B15) -> 112580 | C10: =SUM(C11:C15) -> 130163.89 | D10: =SUM(D11:D15) -> 116889 | E10: =SUM(E11:E15) -> 180668.23 | F10: =SUM(F11:F15) -> 118150.2 | G10: =SUM(G11:G15) -> 132020.43
A11: Angažirana OS | B11: ='INV+AM'!C8 -> 112580 | K11: IRR | L11: =IRR(B16:G16) -> 1.0844058
A12: Angažirana TOBS | B12: 0 | C12: =TOBS!D30 -> -14588.873 | D12: =TOBS!E30-TOBS!D30 -> 78.245525 | E12: =TOBS!F30-TOBS!E30 -> 1373.0649 | F12: =TOBS!G30-TOBS!F30 -> -426.79371 | G12: =TOBS!H30-TOBS!G30 -> 179.61264
A13: Troškovi materijala i usluga | C13: =SUM(RDG!C5,RDG!C6,RDG!C7,RDG!C9,RDG!C10) -> 45552 | D13: =SUM(RDG!D5,RDG!D6,RDG!D7,RDG!D9,RDG!D10) -> 33672 | E13: =SUM(RDG!E5,RDG!E6,RDG!E7,RDG!E9,RDG!E10) -> 48120 | F13: =SUM(RDG!F6,RDG!F5,RDG!F7,RDG!F9,RDG!F10) -> 28200 | G13: =SUM(RDG!G5,RDG!G6,RDG!G7,RDG!G9,RDG!G10) -> 33840 | K13: Provjera interne stope rentabilnosti | M13: Diskontna stopa | N13: =L11 -> 1.0844058
A14: Izdaci za osoblje | C14: =RDG!C8 -> 73440 | D14: =RDG!D8 -> 73440 | E14: =RDG!E8 -> 73440 | F14: =RDG!F8 -> 73440 | G14: =RDG!G8 -> 73440 | K14: Godina projekta | L14: 0 | M14: 1 | N14: 2 | O14: 3 | P14: 4 | Q14: 5
A15: Porezi | C15: =RDG!C15 -> 25760.76 | D15: =RDG!D15 -> 9698.7568 | E15: =RDG!E15 -> 57735.163 | F15: =RDG!F15 -> 16936.998 | G15: =RDG!G15 -> 24560.82 | K15: DNT | L15: =B16*1/(1+$N$13)^L14 -> -112580 | M15: =C16*1/(1+$N$13)^M14 -> 64899.125 | N15: =D16*1/(1+$N$13)^N14 -> 12923.88 | O15: =E16*1/(1+$N$13)^O14 -> 27222.379 | P15: =F16*1/(1+$N$13)^P14 -> 4484.3222 | Q15: =G16*1/(1+$N$13)^Q14 -> 3050.2934
A16: III NETO PRIMICI | B16: =B5-B10 -> -112580 | C16: =C5-C10 -> 135276.11 | D16: =D5-D10 -> 56150.998 | E16: =E5-E10 -> 246531.77 | F16: =F5-F10 -> 84649.795 | G16: =G5-G10 -> 120019.82 | K16: Kumulativ DNT | L16: =L15 -> -112580 | M16: =L16+M15 -> -47680.875 | N16: =M16+N15 -> -34756.994 | O16: =N16+O15 -> -7534.6156 | P16: =O16+P15 -> -3050.2934 | Q16: =P16+Q15 -> 2.2737368e-11
A17: IV KUMULATIV NETO PRIMITKA | B17: =B16 -> -112580 | C17: =B17+C16 -> 22696.113 | D17: =C17+D16 -> 78847.111 | E17: =D17+E16 -> 325378.88 | F17: =E17+F16 -> 410028.68 | G17: =F17+G16 -> 530048.5
K18: Indeks profitabilnosti | L18: =L19/L20 -> 5.7081942
A19: Vrijeme povrata | B19: =F4+(-G16)/F17 -> 3.7072892 | K19: Suma DNT(4%) | L19: =SUM(C16:G16) -> 642628.5
K20: Ulaganje | L20: =B11 -> 112580
A23: Likvidnost projekta
A24: FINANCIJSKI TIJEK
A25: OPIS | B25: 2025 | C25: 2026 | D25: 2027 | E25: 2028 | F25: 2029 | G25: 2030
B26: 0 | C26: 1 | D26: 2 | E26: 3 | F26: 4 | G26: 5
A27: I PRIMICI | B27: =SUM(B28:B29,B32) -> 175160 | C27: =SUM(C28:C29,C32) -> 265440 | D27: =SUM(D28:D29,D32) -> 173040 | E27: =SUM(E28:E29,E32) -> 427200 | F27: =SUM(F28:F29,F32) -> 202800 | G27: =SUM(G28:G29,G32) -> 252040.26
A28: 1. Ukupni prihod | B28: 0 | C28: =C6 -> 265440 | D28: =D6 -> 173040 | E28: =E6 -> 427200 | F28: =F6 -> 202800 | G28: =G6 -> 244800
A29: 2. Izvori financiranja | B29: =SUM(B30:B31) -> 175160
A30: 2.1. Vlastito ulaganje | B30: ='INV+AM'!C8 -> 112580
A31: 2.2. Kredit | B31: =KREDIT!C3 -> 62580
A32: 3. Ostatak vrijednosti projekta | G32: =G7 -> 7240.256
A33: 3.1. Osnovnih sredstava | G33: =G8 -> 20625
A34: 3.2. Obrtnih sredstava | G34: =G9 -> -13384.744
A35: II IZDACI | B35: =SUM(B36:B37) -> 112580 | C35: =SUM(C37:C41) -> 132667.09 | D35: =SUM(D37:D41) -> 130719.07 | E35: =SUM(E37:E41) -> 194498.3 | F35: =SUM(F37:F41) -> 131980.28 | G35: =SUM(G37:G41) -> 145850.5
A36: 4. Investicije u OS | B36: =B11 -> 112580
A37: 5. Investicije u TOBS | B37: 0 | C37: =C12 -> -14588.873 | D37: =D12 -> 78.245525 | E37: =E12 -> 1373.0649 | F37: =F12 -> -426.79371 | G37: =G12 -> 179.61264
A38: 6. Troškovi materijala i usluga | C38: =C13 -> 45552 | D38: =D13 -> 33672 | E38: =E13 -> 48120 | F38: =F13 -> 28200 | G38: =G13 -> 33840
A39: 7. Izdaci za osoblje | C39: =C14 -> 73440 | D39: =D14 -> 73440 | E39: =E14 -> 73440 | F39: =F14 -> 73440 | G39: =G14 -> 73440
A40: 8. Porezi | C40: =C15 -> 25760.76 | D40: =D15 -> 9698.7568 | E40: =E15 -> 57735.163 | F40: =F15 -> 16936.998 | G40: =G15 -> 24560.82
A41: 9. Otplata (Glavnica + Kamate) | C41: =KREDIT!G6 -> 2503.2 | D41: =KREDIT!H6 -> 13830.071 | E41: =KREDIT!I6 -> 13830.071 | F41: =KREDIT!J6 -> 13830.071 | G41: =KREDIT!K6 -> 13830.071
A42: III NETO PRIMICI | B42: =B27-B35 -> 62580 | C42: =C27-C35 -> 132772.91 | D42: =D27-D35 -> 42320.926 | E42: =E27-E35 -> 232701.7 | F42: =F27-F35 -> 70819.724 | G42: =G27-G35 -> 106189.75
...
